Traceback (most recent call last):
  File "/usr/share/miniconda3/envs/runenv/lib/python3.12/site-packages/jupyter_cache/executors/utils.py", line 58, in single_nb_execution
    executenb(
  File "/usr/share/miniconda3/envs/runenv/lib/python3.12/site-packages/nbclient/client.py", line 1314, in execute
    return NotebookClient(nb=nb, resources=resources, km=km, **kwargs).execute()
           ^^^^^^^^^^^^^^^^^^^^^^^^^^^^^^^^^^^^^^^^^^^^^^^^^^^^^^^^^^^^^^^^^^^^^
  File "/usr/share/miniconda3/envs/runenv/lib/python3.12/site-packages/jupyter_core/utils/__init__.py", line 165, in wrapped
    return loop.run_until_complete(inner)
           ^^^^^^^^^^^^^^^^^^^^^^^^^^^^^^
  File "/usr/share/miniconda3/envs/runenv/lib/python3.12/asyncio/base_events.py", line 687, in run_until_complete
    return future.result()
           ^^^^^^^^^^^^^^^
  File "/usr/share/miniconda3/envs/runenv/lib/python3.12/site-packages/nbclient/client.py", line 709, in async_execute
    await self.async_execute_cell(
  File "/usr/share/miniconda3/envs/runenv/lib/python3.12/site-packages/nbclient/client.py", line 1062, in async_execute_cell
    await self._check_raise_for_error(cell, cell_index, exec_reply)
  File "/usr/share/miniconda3/envs/runenv/lib/python3.12/site-packages/nbclient/client.py", line 918, in _check_raise_for_error
    raise CellExecutionError.from_cell_and_msg(cell, exec_reply_content)
nbclient.exceptions.CellExecutionError: An error occurred while executing the following cell:
------------------
from scipy.interpolate import interp2d
x,y = sp.mgrid[0:1:20j,0:1:20j]  #create the grid 20x20
z = np.cos(4*sp.pi*x)*np.sin(4*sp.pi*y) #initialize the field
T1=interp2d(x,y,z,kind='linear') 
T2=interp2d(x,y,z,kind='cubic') 
T3=interp2d(x,y,z,kind='quintic')
------------------


[0;31m---------------------------------------------------------------------------[0m
[0;31mKeyError[0m                                  Traceback (most recent call last)
File [0;32m/usr/share/miniconda3/envs/runenv/lib/python3.12/site-packages/scipy/__init__.py:137[0m, in [0;36m__getattr__[0;34m(name)[0m
[1;32m    136[0m [38;5;28;01mtry[39;00m:
[0;32m--> 137[0m     [38;5;28;01mreturn[39;00m [38;5;28;43mglobals[39;49m[43m([49m[43m)[49m[43m[[49m[43mname[49m[43m][49m
[1;32m    138[0m [38;5;28;01mexcept[39;00m [38;5;167;01mKeyError[39;00m:

[0;31mKeyError[0m: 'mgrid'

During handling of the above exception, another exception occurred:

[0;31mAttributeError[0m                            Traceback (most recent call last)
Cell [0;32mIn[4], line 2[0m
[1;32m      1[0m [38;5;28;01mfrom[39;00m [38;5;21;01mscipy[39;00m[38;5;21;01m.[39;00m[38;5;21;01minterpolate[39;00m [38;5;28;01mimport[39;00m interp2d
[0;32m----> 2[0m x,y [38;5;241m=[39m [43msp[49m[38;5;241;43m.[39;49m[43mmgrid[49m[[38;5;241m0[39m:[38;5;241m1[39m:[38;5;241m20[39mj,[38;5;241m0[39m:[38;5;241m1[39m:[38;5;241m20[39mj]  [38;5;66;03m#create the grid 20x20[39;00m
[1;32m      3[0m z [38;5;241m=[39m np[38;5;241m.[39mcos([38;5;241m4[39m[38;5;241m*[39msp[38;5;241m.[39mpi[38;5;241m*[39mx)[38;5;241m*[39mnp[38;5;241m.[39msin([38;5;241m4[39m[38;5;241m*[39msp[38;5;241m.[39mpi[38;5;241m*[39my) [38;5;66;03m#initialize the field[39;00m
[1;32m      4[0m T1[38;5;241m=[39minterp2d(x,y,z,kind[38;5;241m=[39m[38;5;124m'[39m[38;5;124mlinear[39m[38;5;124m'[39m) 

File [0;32m/usr/share/miniconda3/envs/runenv/lib/python3.12/site-packages/scipy/__init__.py:139[0m, in [0;36m__getattr__[0;34m(name)[0m
[1;32m    137[0m     [38;5;28;01mreturn[39;00m [38;5;28mglobals[39m()[name]
[1;32m    138[0m [38;5;28;01mexcept[39;00m [38;5;167;01mKeyError[39;00m:
[0;32m--> 139[0m     [38;5;28;01mraise[39;00m [38;5;167;01mAttributeError[39;00m(
[1;32m    140[0m         [38;5;124mf[39m[38;5;124m"[39m[38;5;124mModule [39m[38;5;124m'[39m[38;5;124mscipy[39m[38;5;124m'[39m[38;5;124m has no attribute [39m[38;5;124m'[39m[38;5;132;01m{[39;00mname[38;5;132;01m}[39;00m[38;5;124m'[39m[38;5;124m"[39m
[1;32m    141[0m     )

[0;31mAttributeError[0m: Module 'scipy' has no attribute 'mgrid'

