Traceback (most recent call last):
  File "/usr/share/miniconda3/envs/runenv/lib/python3.12/site-packages/jupyter_cache/executors/utils.py", line 58, in single_nb_execution
    executenb(
  File "/usr/share/miniconda3/envs/runenv/lib/python3.12/site-packages/nbclient/client.py", line 1314, in execute
    return NotebookClient(nb=nb, resources=resources, km=km, **kwargs).execute()
           ^^^^^^^^^^^^^^^^^^^^^^^^^^^^^^^^^^^^^^^^^^^^^^^^^^^^^^^^^^^^^^^^^^^^^
  File "/usr/share/miniconda3/envs/runenv/lib/python3.12/site-packages/jupyter_core/utils/__init__.py", line 165, in wrapped
    return loop.run_until_complete(inner)
           ^^^^^^^^^^^^^^^^^^^^^^^^^^^^^^
  File "/usr/share/miniconda3/envs/runenv/lib/python3.12/asyncio/base_events.py", line 687, in run_until_complete
    return future.result()
           ^^^^^^^^^^^^^^^
  File "/usr/share/miniconda3/envs/runenv/lib/python3.12/site-packages/nbclient/client.py", line 709, in async_execute
    await self.async_execute_cell(
  File "/usr/share/miniconda3/envs/runenv/lib/python3.12/site-packages/nbclient/client.py", line 1062, in async_execute_cell
    await self._check_raise_for_error(cell, cell_index, exec_reply)
  File "/usr/share/miniconda3/envs/runenv/lib/python3.12/site-packages/nbclient/client.py", line 918, in _check_raise_for_error
    raise CellExecutionError.from_cell_and_msg(cell, exec_reply_content)
nbclient.exceptions.CellExecutionError: An error occurred while executing the following cell:
------------------
a = np.linspace(0, 1+1j, 6)
f(a, a)
------------------


[0;31m---------------------------------------------------------------------------[0m
[0;31mTypeError[0m                                 Traceback (most recent call last)
Cell [0;32mIn[25], line 2[0m
[1;32m      1[0m a [38;5;241m=[39m np[38;5;241m.[39mlinspace([38;5;241m0[39m, [38;5;241m1[39m[38;5;241m+[39m[38;5;241m1[39mj, [38;5;241m6[39m)
[0;32m----> 2[0m [43mf[49m[43m([49m[43ma[49m[43m,[49m[43m [49m[43ma[49m[43m)[49m

File [0;32m/usr/share/miniconda3/envs/runenv/lib/python3.12/site-packages/numba/np/ufunc/dufunc.py:287[0m, in [0;36mDUFunc.__call__[0;34m(self, *args, **kws)[0m
[1;32m    285[0m             [38;5;28;01mreturn[39;00m output
[1;32m    286[0m [38;5;28;01melse[39;00m:
[0;32m--> 287[0m     [38;5;28;01mreturn[39;00m [38;5;28;43msuper[39;49m[43m([49m[43m)[49m[38;5;241;43m.[39;49m[38;5;21;43m__call__[39;49m[43m([49m[38;5;241;43m*[39;49m[43margs[49m[43m,[49m[43m [49m[38;5;241;43m*[39;49m[38;5;241;43m*[39;49m[43mkws[49m[43m)[49m

[0;31mTypeError[0m: ufunc 'f' not supported for the input types, and the inputs could not be safely coerced to any supported types according to the casting rule ''safe''

